
[정보] 데이터베이스 이름을 찾고 있습니다...
Traceback (most recent call last):
  File "C:\Users\X0145765\AppData\Local\Programs\Python\Python312\Lib\site-packages\urllib3\connectionpool.py", line 466, in _make_request
    self._validate_conn(conn)
  File "C:\Users\X0145765\AppData\Local\Programs\Python\Python312\Lib\site-packages\urllib3\connectionpool.py", line 1095, in _validate_conn
    conn.connect()
  File "C:\Users\X0145765\AppData\Local\Programs\Python\Python312\Lib\site-packages\urllib3\connection.py", line 730, in connect
    sock_and_verified = _ssl_wrap_socket_and_match_hostname(
                        ^^^^^^^^^^^^^^^^^^^^^^^^^^^^^^^^^^^^
  File "C:\Users\X0145765\AppData\Local\Programs\Python\Python312\Lib\site-packages\urllib3\connection.py", line 909, in _ssl_wrap_socket_and_match_hostname
    ssl_sock = ssl_wrap_socket(
               ^^^^^^^^^^^^^^^^
  File "C:\Users\X0145765\AppData\Local\Programs\Python\Python312\Lib\site-packages\urllib3\util\ssl_.py", line 469, in ssl_wrap_socket
    ssl_sock = _ssl_wrap_socket_impl(sock, context, tls_in_tls, server_hostname)
               ^^^^^^^^^^^^^^^^^^^^^^^^^^^^^^^^^^^^^^^^^^^^^^^^^^^^^^^^^^^^^^^^^
  File "C:\Users\X0145765\AppData\Local\Programs\Python\Python312\Lib\site-packages\urllib3\util\ssl_.py", line 513, in _ssl_wrap_socket_impl
    return ssl_context.wrap_socket(sock, server_hostname=server_hostname)
           ^^^^^^^^^^^^^^^^^^^^^^^^^^^^^^^^^^^^^^^^^^^^^^^^^^^^^^^^^^^^^^
  File "C:\Users\X0145765\AppData\Local\Programs\Python\Python312\Lib\ssl.py", line 455, in wrap_socket
    return self.sslsocket_class._create(
           ^^^^^^^^^^^^^^^^^^^^^^^^^^^^^
  File "C:\Users\X0145765\AppData\Local\Programs\Python\Python312\Lib\ssl.py", line 1042, in _create
    self.do_handshake()
  File "C:\Users\X0145765\AppData\Local\Programs\Python\Python312\Lib\ssl.py", line 1320, in do_handshake
    self._sslobj.do_handshake()
ssl.SSLCertVerificationError: [SSL: CERTIFICATE_VERIFY_FAILED] certificate verify failed: unable to get local issuer certificate (_ssl.c:1000)

During handling of the above exception, another exception occurred:

Traceback (most recent call last):
  File "C:\Users\X0145765\AppData\Local\Programs\Python\Python312\Lib\site-packages\urllib3\connectionpool.py", line 789, in urlopen
    response = self._make_request(
               ^^^^^^^^^^^^^^^^^^^
  File "C:\Users\X0145765\AppData\Local\Programs\Python\Python312\Lib\site-packages\urllib3\connectionpool.py", line 490, in _make_request
    raise new_e
urllib3.exceptions.SSLError: [SSL: CERTIFICATE_VERIFY_FAILED] certificate verify failed: unable to get local issuer certificate (_ssl.c:1000)

The above exception was the direct cause of the following exception:

Traceback (most recent call last):
  File "C:\Users\X0145765\AppData\Local\Programs\Python\Python312\Lib\site-packages\requests\adapters.py", line 667, in send
    resp = conn.urlopen(
           ^^^^^^^^^^^^^
  File "C:\Users\X0145765\AppData\Local\Programs\Python\Python312\Lib\site-packages\urllib3\connectionpool.py", line 843, in urlopen
    retries = retries.increment(
              ^^^^^^^^^^^^^^^^^^
  File "C:\Users\X0145765\AppData\Local\Programs\Python\Python312\Lib\site-packages\urllib3\util\retry.py", line 519, in increment
    raise MaxRetryError(_pool, url, reason) from reason  # type: ignore[arg-type]
    ^^^^^^^^^^^^^^^^^^^^^^^^^^^^^^^^^^^^^^^^^^^^^^^^^^^
urllib3.exceptions.MaxRetryError: HTTPSConnectionPool(host='portal-safety-pnid-basic-dev.api.hcpd03.skhynix.com', port=443): Max retries exceeded with url: /portal-safety-pnid-basic-dev.api.hcpd03.skhynix.com (Caused by SSLError(SSLCertVerificationError(1, '[SSL: CERTIFICATE_VERIFY_FAILED] certificate verify failed: unable to get local issuer certificate (_ssl.c:1000)')))

During handling of the above exception, another exception occurred:

Traceback (most recent call last):
  File "C:\Users\X0145765\Downloads\webtest\sql12.py", line 256, in <module>
    main()
  File "C:\Users\X0145765\Downloads\webtest\sql12.py", line 212, in main
    db_name = get_database_name()
              ^^^^^^^^^^^^^^^^^^^
  File "C:\Users\X0145765\Downloads\webtest\sql12.py", line 37, in get_database_name
    response = send_request(params)
               ^^^^^^^^^^^^^^^^^^^^
  File "C:\Users\X0145765\Downloads\webtest\sql12.py", line 145, in send_request
    return requests.post(url, data=params, timeout=90)
           ^^^^^^^^^^^^^^^^^^^^^^^^^^^^^^^^^^^^^^^^^^^
  File "C:\Users\X0145765\AppData\Local\Programs\Python\Python312\Lib\site-packages\requests\api.py", line 115, in post
    return request("post", url, data=data, json=json, **kwargs)
           ^^^^^^^^^^^^^^^^^^^^^^^^^^^^^^^^^^^^^^^^^^^^^^^^^^^^
  File "C:\Users\X0145765\AppData\Local\Programs\Python\Python312\Lib\site-packages\requests\api.py", line 59, in request
    return session.request(method=method, url=url, **kwargs)
           ^^^^^^^^^^^^^^^^^^^^^^^^^^^^^^^^^^^^^^^^^^^^^^^^^
  File "C:\Users\X0145765\AppData\Local\Programs\Python\Python312\Lib\site-packages\requests\sessions.py", line 589, in request
    resp = self.send(prep, **send_kwargs)
           ^^^^^^^^^^^^^^^^^^^^^^^^^^^^^^
  File "C:\Users\X0145765\AppData\Local\Programs\Python\Python312\Lib\site-packages\requests\sessions.py", line 703, in send
    r = adapter.send(request, **kwargs)
        ^^^^^^^^^^^^^^^^^^^^^^^^^^^^^^^
  File "C:\Users\X0145765\AppData\Local\Programs\Python\Python312\Lib\site-packages\requests\adapters.py", line 698, in send
    raise SSLError(e, request=request)
requests.exceptions.SSLError: HTTPSConnectionPool(host='portal-safety-pnid-basic-dev.api.hcpd03.skhynix.com', port=443): Max retries exceeded with url: /portal-safety-pnid-basic-dev.api.hcpd03.skhynix.com (Caused by SSLError(SSLCertVerificationError(1, '[SSL: CERTIFICATE_VERIFY_FAILED] certificate verify failed: unable to get local issuer certificate (_ssl.c:1000)')))

C:\Users\X0145765\Downloads\webtest>
C:\Users\X0145765\Downloads\webtest>sql12.py

[옵션 선택]
1. 데이터베이스 추출
2. 테이블 추출
3. 컬럼 추출
4. 데이터 추출
5. 종료
작업을 선택하세요: 1
요청 방식을 선택하세요 (GET/POST): POST
[정보] 데이터베이스 이름을 찾고 있습니다...
+-----------------+
| Database Name   |
+=================+
+-----------------+
총 0건

[옵션 선택]
1. 데이터베이스 추출
2. 테이블 추출
3. 컬럼 추출
4. 데이터 추출
5. 종료
작업을 선택하세요: Traceback (most recent call last):
  File "C:\Users\X0145765\Downloads\webtest\sql12.py", line 218, in <module>
    main()
  File "C:\Users\X0145765\Downloads\webtest\sql12.py", line 171, in main
    choice = input("작업을 선택하세요: ")
             ^^^^^^^^^^^^^^^^^^^^^^^^^^^^
KeyboardInterrupt
^C
C:\Users\X0145765\Downloads\webtest>sql12.py

[옵션 선택]
1. 데이터베이스 추출
2. 테이블 추출
3. 컬럼 추출
4. 데이터 추출
5. 종료
작업을 선택하세요: 1
요청 방식을 선택하세요 (GET/POST): POST
[정보] 데이터베이스 이름을 찾고 있습니다...
Traceback (most recent call last):
  File "C:\Users\X0145765\AppData\Local\Programs\Python\Python312\Lib\site-packages\urllib3\connectionpool.py", line 466, in _make_request
    self._validate_conn(conn)
  File "C:\Users\X0145765\AppData\Local\Programs\Python\Python312\Lib\site-packages\urllib3\connectionpool.py", line 1095, in _validate_conn
    conn.connect()
  File "C:\Users\X0145765\AppData\Local\Programs\Python\Python312\Lib\site-packages\urllib3\connection.py", line 730, in connect
    sock_and_verified = _ssl_wrap_socket_and_match_hostname(
                        ^^^^^^^^^^^^^^^^^^^^^^^^^^^^^^^^^^^^
  File "C:\Users\X0145765\AppData\Local\Programs\Python\Python312\Lib\site-packages\urllib3\connection.py", line 909, in _ssl_wrap_socket_and_match_hostname
    ssl_sock = ssl_wrap_socket(
               ^^^^^^^^^^^^^^^^
  File "C:\Users\X0145765\AppData\Local\Programs\Python\Python312\Lib\site-packages\urllib3\util\ssl_.py", line 469, in ssl_wrap_socket
    ssl_sock = _ssl_wrap_socket_impl(sock, context, tls_in_tls, server_hostname)
               ^^^^^^^^^^^^^^^^^^^^^^^^^^^^^^^^^^^^^^^^^^^^^^^^^^^^^^^^^^^^^^^^^
  File "C:\Users\X0145765\AppData\Local\Programs\Python\Python312\Lib\site-packages\urllib3\util\ssl_.py", line 513, in _ssl_wrap_socket_impl
    return ssl_context.wrap_socket(sock, server_hostname=server_hostname)
           ^^^^^^^^^^^^^^^^^^^^^^^^^^^^^^^^^^^^^^^^^^^^^^^^^^^^^^^^^^^^^^
  File "C:\Users\X0145765\AppData\Local\Programs\Python\Python312\Lib\ssl.py", line 455, in wrap_socket
    return self.sslsocket_class._create(
           ^^^^^^^^^^^^^^^^^^^^^^^^^^^^^
  File "C:\Users\X0145765\AppData\Local\Programs\Python\Python312\Lib\ssl.py", line 1042, in _create
    self.do_handshake()
  File "C:\Users\X0145765\AppData\Local\Programs\Python\Python312\Lib\ssl.py", line 1320, in do_handshake
    self._sslobj.do_handshake()
ssl.SSLCertVerificationError: [SSL: CERTIFICATE_VERIFY_FAILED] certificate verify failed: unable to get local issuer certificate (_ssl.c:1000)

During handling of the above exception, another exception occurred:

Traceback (most recent call last):
  File "C:\Users\X0145765\AppData\Local\Programs\Python\Python312\Lib\site-packages\urllib3\connectionpool.py", line 789, in urlopen
    response = self._make_request(
               ^^^^^^^^^^^^^^^^^^^
  File "C:\Users\X0145765\AppData\Local\Programs\Python\Python312\Lib\site-packages\urllib3\connectionpool.py", line 490, in _make_request
    raise new_e
urllib3.exceptions.SSLError: [SSL: CERTIFICATE_VERIFY_FAILED] certificate verify failed: unable to get local issuer certificate (_ssl.c:1000)

The above exception was the direct cause of the following exception:

Traceback (most recent call last):
  File "C:\Users\X0145765\AppData\Local\Programs\Python\Python312\Lib\site-packages\requests\adapters.py", line 667, in send
    resp = conn.urlopen(
           ^^^^^^^^^^^^^
  File "C:\Users\X0145765\AppData\Local\Programs\Python\Python312\Lib\site-packages\urllib3\connectionpool.py", line 843, in urlopen
    retries = retries.increment(
              ^^^^^^^^^^^^^^^^^^
  File "C:\Users\X0145765\AppData\Local\Programs\Python\Python312\Lib\site-packages\urllib3\util\retry.py", line 519, in increment
    raise MaxRetryError(_pool, url, reason) from reason  # type: ignore[arg-type]
    ^^^^^^^^^^^^^^^^^^^^^^^^^^^^^^^^^^^^^^^^^^^^^^^^^^^
urllib3.exceptions.MaxRetryError: HTTPSConnectionPool(host='portal-safety-pnid-basic-dev.api.hcpd03.skhynix.com', port=443): Max retries exceeded with url: /portal-safety-pnid/drawing/drawingfiltertable (Caused by SSLError(SSLCertVerificationError(1, '[SSL: CERTIFICATE_VERIFY_FAILED] certificate verify failed: unable to get local issuer certificate (_ssl.c:1000)')))

During handling of the above exception, another exception occurred:

Traceback (most recent call last):
  File "C:\Users\X0145765\Downloads\webtest\sql12.py", line 218, in <module>
    main()
  File "C:\Users\X0145765\Downloads\webtest\sql12.py", line 180, in main
    db_name = get_database_name()
              ^^^^^^^^^^^^^^^^^^^
  File "C:\Users\X0145765\Downloads\webtest\sql12.py", line 34, in get_database_name
    response = send_request(params)
               ^^^^^^^^^^^^^^^^^^^^
  File "C:\Users\X0145765\Downloads\webtest\sql12.py", line 155, in send_request
    return requests.post(url, data=params, timeout=90)
           ^^^^^^^^^^^^^^^^^^^^^^^^^^^^^^^^^^^^^^^^^^^
  File "C:\Users\X0145765\AppData\Local\Programs\Python\Python312\Lib\site-packages\requests\api.py", line 115, in post
    return request("post", url, data=data, json=json, **kwargs)
           ^^^^^^^^^^^^^^^^^^^^^^^^^^^^^^^^^^^^^^^^^^^^^^^^^^^^
  File "C:\Users\X0145765\AppData\Local\Programs\Python\Python312\Lib\site-packages\requests\api.py", line 59, in request
    return session.request(method=method, url=url, **kwargs)
           ^^^^^^^^^^^^^^^^^^^^^^^^^^^^^^^^^^^^^^^^^^^^^^^^^
  File "C:\Users\X0145765\AppData\Local\Programs\Python\Python312\Lib\site-packages\requests\sessions.py", line 589, in request
    resp = self.send(prep, **send_kwargs)
           ^^^^^^^^^^^^^^^^^^^^^^^^^^^^^^
  File "C:\Users\X0145765\AppData\Local\Programs\Python\Python312\Lib\site-packages\requests\sessions.py", line 703, in send
    r = adapter.send(request, **kwargs)
        ^^^^^^^^^^^^^^^^^^^^^^^^^^^^^^^
  File "C:\Users\X0145765\AppData\Local\Programs\Python\Python312\Lib\site-packages\requests\adapters.py", line 698, in send
    raise SSLError(e, request=request)
requests.exceptions.SSLError: HTTPSConnectionPool(host='portal-safety-pnid-basic-dev.api.hcpd03.skhynix.com', port=443): Max retries exceeded with url: /portal-safety-pnid/drawing/drawingfiltertable (Caused by SSLError(SSLCertVerificationError(1, '[SSL: CERTIFICATE_VERIFY_FAILED] certificate verify failed: unable to get local issuer certificate (_ssl.c:1000)')))
